<?xml version="1.0" encoding="UTF-8"?>
<testng-results skipped="2" failed="1" ignored="0" total="3" passed="0">
  <reporter-output>
  </reporter-output>
  <suite name="Suite" duration-ms="49914" started-at="2020-01-29T16:39:25Z" finished-at="2020-01-29T16:40:15Z">
    <groups>
    </groups>
    <test name="Test" duration-ms="49914" started-at="2020-01-29T16:39:25Z" finished-at="2020-01-29T16:40:15Z">
      <class name="rerun.Testclass">
        <test-method status="PASS" signature="initialization()[pri:0, instance:rerun.Testclass@7921b0a2]" name="initialization" is-config="true" duration-ms="14160" started-at="2020-01-29T16:39:25Z" finished-at="2020-01-29T16:39:39Z">
          <reporter-output>
          </reporter-output>
        </test-method> <!-- initialization -->
        <test-method status="SKIP" signature="test()[pri:0, instance:rerun.Testclass@7921b0a2]" name="test" duration-ms="13" started-at="2020-01-29T16:39:39Z" finished-at="2020-01-29T16:39:39Z">
          <exception class="java.lang.AssertionError">
            <message>
              <![CDATA[expected [true] but found [false]]]>
            </message>
            <full-stacktrace>
              <![CDATA[java.lang.AssertionError: expected [true] but found [false]
at org.testng.Assert.fail(Assert.java:96)
at org.testng.Assert.failNotEquals(Assert.java:776)
at org.testng.Assert.assertEqualsImpl(Assert.java:137)
at org.testng.Assert.assertEquals(Assert.java:118)
at org.testng.Assert.assertEquals(Assert.java:568)
at org.testng.Assert.assertEquals(Assert.java:578)
at rerun.Testclass.test(Testclass.java:22)
at sun.reflect.NativeMethodAccessorImpl.invoke0(Native Method)
at sun.reflect.NativeMethodAccessorImpl.invoke(Unknown Source)
at sun.reflect.DelegatingMethodAccessorImpl.invoke(Unknown Source)
at java.lang.reflect.Method.invoke(Unknown Source)
at org.testng.internal.MethodInvocationHelper.invokeMethod(MethodInvocationHelper.java:124)
at org.testng.internal.Invoker.invokeMethod(Invoker.java:583)
at org.testng.internal.Invoker.invokeTestMethod(Invoker.java:719)
at org.testng.internal.Invoker.invokeTestMethods(Invoker.java:989)
at org.testng.internal.TestMethodWorker.invokeTestMethods(TestMethodWorker.java:125)
at org.testng.internal.TestMethodWorker.run(TestMethodWorker.java:109)
at org.testng.TestRunner.privateRun(TestRunner.java:648)
at org.testng.TestRunner.run(TestRunner.java:505)
at org.testng.SuiteRunner.runTest(SuiteRunner.java:455)
at org.testng.SuiteRunner.runSequentially(SuiteRunner.java:450)
at org.testng.SuiteRunner.privateRun(SuiteRunner.java:415)
at org.testng.SuiteRunner.run(SuiteRunner.java:364)
at org.testng.SuiteRunnerWorker.runSuite(SuiteRunnerWorker.java:52)
at org.testng.SuiteRunnerWorker.run(SuiteRunnerWorker.java:84)
at org.testng.TestNG.runSuitesSequentially(TestNG.java:1208)
at org.testng.TestNG.runSuitesLocally(TestNG.java:1137)
at org.testng.TestNG.runSuites(TestNG.java:1049)
at org.testng.TestNG.run(TestNG.java:1017)
at org.testng.remote.AbstractRemoteTestNG.run(AbstractRemoteTestNG.java:114)
at org.testng.remote.RemoteTestNG.initAndRun(RemoteTestNG.java:251)
at org.testng.remote.RemoteTestNG.main(RemoteTestNG.java:77)
]]>
            </full-stacktrace>
          </exception> <!-- java.lang.AssertionError -->
          <reporter-output>
          </reporter-output>
        </test-method> <!-- test -->
        <test-method status="PASS" signature="teardown()[pri:0, instance:rerun.Testclass@7921b0a2]" name="teardown" is-config="true" duration-ms="4377" started-at="2020-01-29T16:39:39Z" finished-at="2020-01-29T16:39:44Z">
          <reporter-output>
          </reporter-output>
        </test-method> <!-- teardown -->
        <test-method status="PASS" signature="initialization()[pri:0, instance:rerun.Testclass@7921b0a2]" name="initialization" is-config="true" duration-ms="11836" started-at="2020-01-29T16:39:44Z" finished-at="2020-01-29T16:39:56Z">
          <reporter-output>
          </reporter-output>
        </test-method> <!-- initialization -->
        <test-method status="SKIP" signature="test()[pri:0, instance:rerun.Testclass@7921b0a2]" name="test" duration-ms="2" started-at="2020-01-29T16:39:56Z" finished-at="2020-01-29T16:39:56Z">
          <exception class="java.lang.AssertionError">
            <message>
              <![CDATA[expected [true] but found [false]]]>
            </message>
            <full-stacktrace>
              <![CDATA[java.lang.AssertionError: expected [true] but found [false]
at org.testng.Assert.fail(Assert.java:96)
at org.testng.Assert.failNotEquals(Assert.java:776)
at org.testng.Assert.assertEqualsImpl(Assert.java:137)
at org.testng.Assert.assertEquals(Assert.java:118)
at org.testng.Assert.assertEquals(Assert.java:568)
at org.testng.Assert.assertEquals(Assert.java:578)
at rerun.Testclass.test(Testclass.java:22)
at sun.reflect.NativeMethodAccessorImpl.invoke0(Native Method)
at sun.reflect.NativeMethodAccessorImpl.invoke(Unknown Source)
at sun.reflect.DelegatingMethodAccessorImpl.invoke(Unknown Source)
at java.lang.reflect.Method.invoke(Unknown Source)
at org.testng.internal.MethodInvocationHelper.invokeMethod(MethodInvocationHelper.java:124)
at org.testng.internal.Invoker.invokeMethod(Invoker.java:583)
at org.testng.internal.Invoker.retryFailed(Invoker.java:839)
at org.testng.internal.Invoker.invokeTestMethods(Invoker.java:1010)
at org.testng.internal.TestMethodWorker.invokeTestMethods(TestMethodWorker.java:125)
at org.testng.internal.TestMethodWorker.run(TestMethodWorker.java:109)
at org.testng.TestRunner.privateRun(TestRunner.java:648)
at org.testng.TestRunner.run(TestRunner.java:505)
at org.testng.SuiteRunner.runTest(SuiteRunner.java:455)
at org.testng.SuiteRunner.runSequentially(SuiteRunner.java:450)
at org.testng.SuiteRunner.privateRun(SuiteRunner.java:415)
at org.testng.SuiteRunner.run(SuiteRunner.java:364)
at org.testng.SuiteRunnerWorker.runSuite(SuiteRunnerWorker.java:52)
at org.testng.SuiteRunnerWorker.run(SuiteRunnerWorker.java:84)
at org.testng.TestNG.runSuitesSequentially(TestNG.java:1208)
at org.testng.TestNG.runSuitesLocally(TestNG.java:1137)
at org.testng.TestNG.runSuites(TestNG.java:1049)
at org.testng.TestNG.run(TestNG.java:1017)
at org.testng.remote.AbstractRemoteTestNG.run(AbstractRemoteTestNG.java:114)
at org.testng.remote.RemoteTestNG.initAndRun(RemoteTestNG.java:251)
at org.testng.remote.RemoteTestNG.main(RemoteTestNG.java:77)
]]>
            </full-stacktrace>
          </exception> <!-- java.lang.AssertionError -->
          <reporter-output>
          </reporter-output>
        </test-method> <!-- test -->
        <test-method status="PASS" signature="teardown()[pri:0, instance:rerun.Testclass@7921b0a2]" name="teardown" is-config="true" duration-ms="4126" started-at="2020-01-29T16:39:56Z" finished-at="2020-01-29T16:40:00Z">
          <reporter-output>
          </reporter-output>
        </test-method> <!-- teardown -->
        <test-method status="PASS" signature="initialization()[pri:0, instance:rerun.Testclass@7921b0a2]" name="initialization" is-config="true" duration-ms="11220" started-at="2020-01-29T16:40:00Z" finished-at="2020-01-29T16:40:11Z">
          <reporter-output>
          </reporter-output>
        </test-method> <!-- initialization -->
        <test-method status="FAIL" signature="test()[pri:0, instance:rerun.Testclass@7921b0a2]" name="test" duration-ms="2" started-at="2020-01-29T16:40:11Z" finished-at="2020-01-29T16:40:11Z">
          <exception class="java.lang.AssertionError">
            <message>
              <![CDATA[expected [true] but found [false]]]>
            </message>
            <full-stacktrace>
              <![CDATA[java.lang.AssertionError: expected [true] but found [false]
at org.testng.Assert.fail(Assert.java:96)
at org.testng.Assert.failNotEquals(Assert.java:776)
at org.testng.Assert.assertEqualsImpl(Assert.java:137)
at org.testng.Assert.assertEquals(Assert.java:118)
at org.testng.Assert.assertEquals(Assert.java:568)
at org.testng.Assert.assertEquals(Assert.java:578)
at rerun.Testclass.test(Testclass.java:22)
at sun.reflect.NativeMethodAccessorImpl.invoke0(Native Method)
at sun.reflect.NativeMethodAccessorImpl.invoke(Unknown Source)
at sun.reflect.DelegatingMethodAccessorImpl.invoke(Unknown Source)
at java.lang.reflect.Method.invoke(Unknown Source)
at org.testng.internal.MethodInvocationHelper.invokeMethod(MethodInvocationHelper.java:124)
at org.testng.internal.Invoker.invokeMethod(Invoker.java:583)
at org.testng.internal.Invoker.retryFailed(Invoker.java:839)
at org.testng.internal.Invoker.invokeTestMethods(Invoker.java:1010)
at org.testng.internal.TestMethodWorker.invokeTestMethods(TestMethodWorker.java:125)
at org.testng.internal.TestMethodWorker.run(TestMethodWorker.java:109)
at org.testng.TestRunner.privateRun(TestRunner.java:648)
at org.testng.TestRunner.run(TestRunner.java:505)
at org.testng.SuiteRunner.runTest(SuiteRunner.java:455)
at org.testng.SuiteRunner.runSequentially(SuiteRunner.java:450)
at org.testng.SuiteRunner.privateRun(SuiteRunner.java:415)
at org.testng.SuiteRunner.run(SuiteRunner.java:364)
at org.testng.SuiteRunnerWorker.runSuite(SuiteRunnerWorker.java:52)
at org.testng.SuiteRunnerWorker.run(SuiteRunnerWorker.java:84)
at org.testng.TestNG.runSuitesSequentially(TestNG.java:1208)
at org.testng.TestNG.runSuitesLocally(TestNG.java:1137)
at org.testng.TestNG.runSuites(TestNG.java:1049)
at org.testng.TestNG.run(TestNG.java:1017)
at org.testng.remote.AbstractRemoteTestNG.run(AbstractRemoteTestNG.java:114)
at org.testng.remote.RemoteTestNG.initAndRun(RemoteTestNG.java:251)
at org.testng.remote.RemoteTestNG.main(RemoteTestNG.java:77)
]]>
            </full-stacktrace>
          </exception> <!-- java.lang.AssertionError -->
          <reporter-output>
          </reporter-output>
        </test-method> <!-- test -->
        <test-method status="PASS" signature="teardown()[pri:0, instance:rerun.Testclass@7921b0a2]" name="teardown" is-config="true" duration-ms="4120" started-at="2020-01-29T16:40:11Z" finished-at="2020-01-29T16:40:15Z">
          <reporter-output>
          </reporter-output>
        </test-method> <!-- teardown -->
      </class> <!-- rerun.Testclass -->
    </test> <!-- Test -->
  </suite> <!-- Suite -->
</testng-results>
